<?xml version="1.0" ?>
<!-- =================================================================================== -->
<!-- |    This document was autogenerated by xacro from /home/vedh/catkin_ws/src/eYRC-2022_HolA_Bot/adhic4_description/urdf/adhic4.xacro | -->
<!-- |    EDITING THIS FILE BY HAND IS NOT RECOMMENDED                                 | -->
<!-- =================================================================================== -->
<robot name="adhic4">
    <material name="silver">
        <color rgba="0.700 0.700 0.700 1.000" />
    </material>
    <transmission name="Revolute1_tran">
        <type>transmission_interface/SimpleTransmission</type>
        <joint name="Revolute1">
            <hardwareInterface>hardware_interface/EffortJointInterface</hardwareInterface>
        </joint>
        <actuator name="Revolute1_actr">
            <hardwareInterface>hardware_interface/EffortJointInterface</hardwareInterface>
            <mechanicalReduction>1</mechanicalReduction>
        </actuator>
    </transmission>
    <transmission name="Revolute2_tran">
        <type>transmission_interface/SimpleTransmission</type>
        <joint name="Revolute2">
            <hardwareInterface>hardware_interface/EffortJointInterface</hardwareInterface>
        </joint>
        <actuator name="Revolute2_actr">
            <hardwareInterface>hardware_interface/EffortJointInterface</hardwareInterface>
            <mechanicalReduction>1</mechanicalReduction>
        </actuator>
    </transmission>
    <transmission name="Revolute3_tran">
        <type>transmission_interface/SimpleTransmission</type>
        <joint name="Revolute3">
            <hardwareInterface>hardware_interface/EffortJointInterface</hardwareInterface>
        </joint>
        <actuator name="Revolute3_actr">
            <hardwareInterface>hardware_interface/EffortJointInterface</hardwareInterface>
            <mechanicalReduction>1</mechanicalReduction>
        </actuator>
    </transmission>
    <gazebo>
        <plugin filename="libgazebo_ros_control.so" name="control" />
        <plugin name="gazebo_ros_control">
            <robotNamespace>/</robotNamespace>
        </plugin>
    </gazebo>
    <gazebo reference="base_link">
        <material>Gazebo/Silver</material>
        <mu1>0.2</mu1>
        <mu2>0.2</mu2>
        <selfCollide>true</selfCollide>
        <gravity>true</gravity>
    </gazebo>
    <gazebo reference="front_wheel_1">
        <material>Gazebo/Silver</material>
        <mu1>0.2</mu1>
        <mu2>0.2</mu2>
        <selfCollide>true</selfCollide>
    </gazebo>
    <gazebo reference="left_wheel_1">
        <material>Gazebo/Silver</material>
        <mu1>0.2</mu1>
        <mu2>0.2</mu2>
        <selfCollide>true</selfCollide>
    </gazebo>
    <gazebo reference="right_wheel_1">
        <material>Gazebo/Silver</material>
        <mu1>0.2</mu1>
        <mu2>0.2</mu2>
        <selfCollide>true</selfCollide>
    </gazebo>
    <gazebo reference="lidar_1_1">
        <material>Gazebo/Silver</material>
        <mu1>0.2</mu1>
        <mu2>0.2</mu2>
        <selfCollide>true</selfCollide>
    </gazebo>
    <gazebo>
        <plugin filename="libgazebo_ros_planar_move.so" name="object_controller" />
    </gazebo>
    <gazebo>
        <plugin filename="libcustom_force.so" name="right_force">
            <bodyName>right_wheel_1</bodyName>
            <topicName>right_wheel_force</topicName>
        </plugin>
    </gazebo>
    <gazebo>
        <plugin filename="libcustom_force.so" name="left_force">
            <bodyName>left_wheel_1</bodyName>
            <topicName>left_wheel_force</topicName>
        </plugin>
    </gazebo>
    <gazebo>
        <plugin filename="libcustom_force.so" name="front_force">
            <bodyName>front_wheel_1</bodyName>
            <topicName>front_wheel_force</topicName>
        </plugin>
    </gazebo>
    <!-- hokuyo -->
    <gazebo reference="lidar_1_1">
        <sensor name="head_hokuyo_sensor" type="ray">
            <pose>0 0 0 0 0 0</pose>
            <visualize>true</visualize>
            <update_rate>40</update_rate>
            <ray>
                <scan>
                    <horizontal>
                        <samples>720</samples>
                        <resolution>1</resolution>
                        <min_angle>-1.570796</min_angle>
                        <max_angle>1.570796</max_angle>
                    </horizontal>
                </scan>
                <range>
                    <min>0.10</min>
                    <max>2</max>
                    <resolution>0.01</resolution>
                </range>
                <noise>
                    <type>gaussian</type>
                    <mean>0.0</mean>
                    <stddev>0.01</stddev>
                </noise>
            </ray>
            <plugin filename="libgazebo_ros_laser.so" name="gazebo_ros_head_hokuyo_controller">
                <topicName>/bot/scan</topicName>
                <frameName>lidar_1_1</frameName>
            </plugin>
        </sensor>
    </gazebo>
    <link name="base_footprint" />
    <link name="hbot_base">
        <inertial>
            <origin rpy="0 0 0" xyz="0.018156704502869988 -0.0074033581631362325 0.18794645946750038" />
            <mass value="208.37705429986153" />
            <inertia ixx="7.371857" ixy="-0.00061" ixz="-0.000131" iyy="7.368891" iyz="-4.5e-05" izz="13.35531" />
        </inertial>
        <visual>
            <origin rpy="0 0 0" xyz="0 0 0.22" />
            <geometry>
                <mesh filename="package://adhic4_description/meshes/base_link.stl" scale="0.0005 0.0005 0.0005" />
            </geometry>
            <material name="silver" />
        </visual>
        <collision>
            <origin rpy="0 0 0" xyz="0 0 0.22" />
            <geometry>
                <mesh filename="package://adhic4_description/meshes/base_link.stl" scale="0.0005 0.0005 0.0005" />
            </geometry>
        </collision>
    </link>
    <joint name="j1" type="fixed">
        <parent link="base_footprint" />
        <child link="hbot_base" />
    </joint>
    <link name="front_wheel_1">
        <inertial>
            <origin rpy="0 0 0" xyz="0.030000153152309306 4.022506844893539e-06 -3.814697197013217e-09" />
            <mass value="30.68285473973862" />
            <inertia ixx="0.31812" ixy="2e-05" ixz="0.0" iyy="0.168265" iyz="0.0" izz="0.168265" />
        </inertial>
        <visual>
            <origin rpy="0 0 0" xyz="-0.426061 0.007854 0.075" />
            <geometry>
                <mesh filename="package://adhic4_description/meshes/front_wheel_1.stl" scale="0.0005 0.0005 0.0005" />
            </geometry>
            <material name="silver" />
        </visual>
        <collision>
            <origin rpy="0 0 0" xyz="-0.426061 0.007854 0.075" />
            <geometry>
                <mesh filename="package://adhic4_description/meshes/front_wheel_1.stl" scale="0.0005 0.0005 0.0005" />
            </geometry>
        </collision>
    </link>
    <link name="left_wheel_1">
        <inertial>
            <origin rpy="0 0 0" xyz="-0.0149998607647496 0.025980765634774194 -3.814698668058725e-09" />
            <mass value="30.68285473973862" />
            <inertia ixx="0.205729" ixy="-0.064889" ixz="-0.0" iyy="0.280656" iyz="0.0" izz="0.168265" />
        </inertial>
        <visual>
            <origin rpy="0 0 0" xyz="0.185829 -0.345941 0.075" />
            <geometry>
                <mesh filename="package://adhic4_description/meshes/left_wheel_1.stl" scale="0.0005 0.0005 0.0005" />
            </geometry>
            <material name="silver" />
        </visual>
        <collision>
            <origin rpy="0 0 0" xyz="0.185829 -0.345941 0.075" />
            <geometry>
                <mesh filename="package://adhic4_description/meshes/left_wheel_1.stl" scale="0.0005 0.0005 0.0005" />
            </geometry>
        </collision>
    </link>
    <link name="right_wheel_1">
        <inertial>
            <origin rpy="0 0 0" xyz="-0.014994788089180644 -0.025983621299543846 -3.814697280279944e-09" />
            <mass value="30.682854739738648" />
            <inertia ixx="0.205703" ixy="0.064874" ixz="0.0" iyy="0.280682" iyz="0.0" izz="0.168265" />
        </inertial>
        <visual>
            <origin rpy="0 0 0" xyz="0.186434 0.360531 0.075" />
            <geometry>
                <mesh filename="package://adhic4_description/meshes/right_wheel_1.stl" scale="0.0005 0.0005 0.0005" />
            </geometry>
            <material name="silver" />
        </visual>
        <collision>
            <origin rpy="0 0 0" xyz="0.186434 0.360531 0.075" />
            <geometry>
                <mesh filename="package://adhic4_description/meshes/right_wheel_1.stl" scale="0.0005 0.0005 0.0005" />
            </geometry>
        </collision>
    </link>
    <link name="lidar_1_1">
        <inertial>
            <origin rpy="0 0 0" xyz="1.5554700822859036e-07 -3.886178115870831e-07 0.02380807279672631" />
            <mass value="10.797829000846852" />
            <inertia ixx="0.026687" ixy="0.0" ixz="-0.0" iyy="0.026687" iyz="0.0" izz="0.049282" />
        </inertial>
        <visual>
            <origin rpy="0 0 0" xyz="-0.018171 0.007397 -0.129" />
            <geometry>
                <mesh filename="package://adhic4_description/meshes/lidar_1_1.stl" scale="0.0005 0.0005 0.0005" />
            </geometry>
            <material name="silver" />
        </visual>
        <collision>
            <origin rpy="0 0 0" xyz="-0.018171 0.007397 -0.129" />
            <geometry>
                <mesh filename="package://adhic4_description/meshes/lidar_1_1.stl" scale="0.0005 0.0005 0.0005" />
            </geometry>
        </collision>
    </link>
    <link name="hbot_base_up">
        <inertial>
            <origin rpy="0 0 0" xyz="0.018156704502869988 -0.0074033581631362325 0.18794645946750038" />
            <mass value="208.37705429986153" />
            <inertia ixx="7.371857" ixy="-0.00061" ixz="-0.000131" iyy="7.368891" iyz="-4.5e-05" izz="13.35531" />
        </inertial>
        <visual>
            <origin rpy="0 0 0" xyz="0 0 0.22" />
            <geometry>
                <mesh filename="package://adhic4_description/meshes/base_link.stl" scale="0.0005 0.0005 0.0005" />
            </geometry>
            <material name="silver" />
        </visual>
        <collision>
            <origin rpy="0 0 0" xyz="0 0 0.22" />
            <geometry>
                <mesh filename="package://adhic4_description/meshes/base_link.stl" scale="0.0005 0.0005 0.0005" />
            </geometry>
        </collision>
    </link>
    <link name="display">
        <visual>
            <geometry>
                <box size="0.15 0.3 0.01" />
            </geometry>
            <material name="white">
                <color rgba="1 1 1 1" />
            </material>
        </visual>
        <collision>
            <geometry>
                <box size="0.1 0.1 0.1" />
            </geometry>
        </collision>
        <inertial>
            <mass value="20" />
            <inertia ixx="0.268256" ixy="0" ixz="0.0" iyy="0.533312" iyz="0.0" izz="0.268256" />
            <origin xyz="0 0 0" rpy="0 0 0" />
        </inertial>
    </link>
    <joint name="laser_scanner_joint" type="fixed">
        <axis xyz="0.0 1 0.0" />
        <parent link="hbot_base_up" />
        <child link="display" />
        <origin rpy="0.0 1.0 0.0" xyz="0.16 0.0 0.27" />
    </joint>
    <joint name="fixed55" type="fixed">
        <origin rpy="0 0 0" xyz="0.0 0.0 0.145" />
        <parent link="hbot_base" />
        <child link="hbot_base_up" />
        <axis xyz="1.0 0.000132 0.0" />
    </joint>
    <joint name="Revolute1" type="continuous">
        <origin rpy="0 0 0" xyz="0.426061 -0.007854 0.145" />
        <parent link="hbot_base" />
        <child link="front_wheel_1" />
        <axis xyz="1.0 0.000132 0.0" />
    </joint>
    <joint name="Revolute2" type="continuous">
        <origin rpy="0 0 0" xyz="-0.185829 0.345941 0.145" />
        <parent link="hbot_base" />
        <child link="left_wheel_1" />
        <axis xyz="-0.5 0.866025 0.0" />
    </joint>
    <joint name="Revolute3" type="continuous">
        <origin rpy="0 0 0" xyz="-0.186434 -0.360531 0.145" />
        <parent link="hbot_base" />
        <child link="right_wheel_1" />
        <axis xyz="-0.499827 -0.866126 0.0" />
    </joint>
    <joint name="Rigid 4" type="fixed">
        <origin rpy="0 0 0" xyz="0.018171 -0.007397 0.349" />
        <parent link="hbot_base" />
        <child link="lidar_1_1" />
    </joint>
    <!-- measured from model -->
    <!--property name="shoulder_height" value="0.089159" /-->
    <!--property name="shoulder_offset" value="0.13585" /-->
    <!-- shoulder_offset - elbow_offset + wrist_1_length = 0.10915 -->
    <!--property name="upper_arm_length" value="0.42500" /-->
    <!--property name="elbow_offset" value="0.1197" /-->
    <!-- CAD measured -->
    <!--property name="forearm_length" value="0.39225" /-->
    <!--property name="wrist_1_length" value="0.093" /-->
    <!-- CAD measured -->
    <!--property name="wrist_2_length" value="0.09465" /-->
    <!-- In CAD this distance is 0.930, but in the spec it is 0.09465 -->
    <!--property name="wrist_3_length" value="0.0823" /-->
    <!-- manually measured -->
    <link name="base_link">
        <visual>
            <geometry>
                <mesh filename="package://ur_description/meshes/ur5/visual/base.dae" />
            </geometry>
            <material name="LightGrey">
                <color rgba="0.7 0.7 0.7 1.0" />
            </material>
        </visual>
        <collision>
            <geometry>
                <!--           <mesh filename="package://ur_description/meshes/ur5/collision/base.stl" /> -->
                <cylinder length="0.024" radius="0.0735" />
            </geometry>
        </collision>
        <inertial>
            <mass value="4.0" />
            <origin rpy="0 0 0" xyz="0.0 0.0 0.0" />
            <inertia ixx="0.00443333156" ixy="0.0" ixz="0.0" iyy="0.00443333156" iyz="0.0" izz="0.0072" />
        </inertial>
    </link>
    <joint name="shoulder_pan_joint" type="revolute">
        <parent link="base_link" />
        <child link="shoulder_link" />
        <origin rpy="0.0 0.0 0.0" xyz="0.0 0.0 0.089159" />
        <axis xyz="0 0 1" />
        <limit effort="150.0" lower="-6.283185307179586" upper="6.283185307179586" velocity="3.15" />
        <dynamics damping="0.0" friction="0.0" />
    </joint>
    <link name="shoulder_link">
        <visual>
            <geometry>
                <mesh filename="package://ur_description/meshes/ur5/visual/shoulder.dae" />
            </geometry>
            <material name="LightGrey">
                <color rgba="0.7 0.7 0.7 1.0" />
            </material>
        </visual>
        <collision>
            <geometry>
                <!-- <mesh filename="package://ur_description/meshes/ur5/collision/shoulder.stl" /> -->
                <cylinder length="0.134" radius="0.0595" />
            </geometry>
        </collision>
        <inertial>
            <mass value="3.7" />
            <origin rpy="0 0 0" xyz="0.0 0.0 0.0" />
            <inertia ixx="0.010267495893" ixy="0.0" ixz="0.0" iyy="0.010267495893" iyz="0.0" izz="0.00666" />
        </inertial>
    </link>
    <joint name="shoulder_lift_joint" type="revolute">
        <parent link="shoulder_link" />
        <child link="upper_arm_link" />
        <origin rpy="0.0 -0.7853981633974483 0.0" xyz="0.0 0.13585 0.0" />
        <axis xyz="0 1 0" />
        <limit effort="150.0" lower="-6.283185307179586" upper="6.283185307179586" velocity="3.15" />
        <dynamics damping="0.0" friction="0.0" />
    </joint>
    <link name="upper_arm_link">
        <visual>
            <geometry>
                <mesh filename="package://ur_description/meshes/ur5/visual/upperarm.dae" />
            </geometry>
            <material name="LightGrey">
                <color rgba="0.7 0.7 0.7 1.0" />
            </material>
        </visual>
        <collision>
            <origin rpy="0 0 0" xyz="0.0 0.0 0.22" />
            <geometry>
                <!--  <mesh filename="package://ur_description/meshes/ur5/collision/upperarm.stl" /> -->
                <cylinder length="0.545" radius="0.0450" />
            </geometry>
        </collision>
        <inertial>
            <mass value="8.393" />
            <origin rpy="0 0 0" xyz="0.0 0.0 0.28" />
            <inertia ixx="0.22689067591036005" ixy="0.0" ixz="0.0" iyy="0.22689067591036005" iyz="0.0" izz="0.0151074" />
        </inertial>
    </link>
    <joint name="elbow_joint" type="revolute">
        <parent link="upper_arm_link" />
        <child link="forearm_link" />
        <origin rpy="0.0 2.356194490192345 0.0" xyz="0.0 -0.1197 0.425" />
        <axis xyz="0 1 0" />
        <limit effort="150.0" lower="-3.141592653589793" upper="3.141592653589793" velocity="3.15" />
        <dynamics damping="0.0" friction="0.0" />
    </joint>
    <link name="forearm_link">
        <visual>
            <geometry>
                <mesh filename="package://ur_description/meshes/ur5/visual/forearm.dae" />
            </geometry>
            <material name="LightGrey">
                <color rgba="0.7 0.7 0.7 1.0" />
            </material>
        </visual>
        <collision>
            <origin rpy="0 0 0" xyz="0.0 0.0 0.18" />
            <geometry>
                <!--  <mesh filename="package://ur_description/meshes/ur5/collision/forearm.stl" /> -->
                <cylinder length="0.489" radius="0.0380" />
            </geometry>
        </collision>
        <inertial>
            <mass value="2.275" />
            <origin rpy="0 0 0" xyz="0.0 0.0 0.196125" />
            <inertia ixx="0.03121679102890359" ixy="0.0" ixz="0.0" iyy="0.03121679102890359" iyz="0.0" izz="0.004095" />
        </inertial>
    </link>
    <joint name="wrist_1_joint" type="revolute">
        <parent link="forearm_link" />
        <child link="wrist_1_link" />
        <origin rpy="0.0 1.5707963267948966 0.0" xyz="0.0 0.0 0.39225" />
        <axis xyz="0 1 0" />
        <limit effort="28.0" lower="-6.283185307179586" upper="6.283185307179586" velocity="3.2" />
        <dynamics damping="0.0" friction="0.0" />
    </joint>
    <link name="wrist_1_link">
        <visual>
            <geometry>
                <mesh filename="package://ur_description/meshes/ur5/visual/wrist1.dae" />
            </geometry>
            <material name="LightGrey">
                <color rgba="0.7 0.7 0.7 1.0" />
            </material>
        </visual>
        <collision>
            <origin rpy="0 0 0" xyz="0.0 0.093 0.008" />
            <geometry>
                <!--  <mesh filename="package://ur_description/meshes/ur5/collision/wrist1.stl" /> -->
                <cylinder length="0.100" radius="0.0320" />
            </geometry>
        </collision>
        <inertial>
            <mass value="1.219" />
            <origin rpy="0 0 0" xyz="0.0 0.093 0.0" />
            <inertia ixx="0.0025598989760400002" ixy="0.0" ixz="0.0" iyy="0.0025598989760400002" iyz="0.0" izz="0.0021942" />
        </inertial>
    </link>
    <joint name="wrist_2_joint" type="revolute">
        <parent link="wrist_1_link" />
        <child link="wrist_2_link" />
        <origin rpy="0.0 0.0 1.5707963267948966" xyz="0.0 0.093 0.0" />
        <axis xyz="0 0 1" />
        <limit effort="28.0" lower="-6.283185307179586" upper="6.283185307179586" velocity="3.2" />
        <dynamics damping="0.0" friction="0.0" />
    </joint>
    <link name="wrist_2_link">
        <visual>
            <geometry>
                <mesh filename="package://ur_description/meshes/ur5/visual/wrist2.dae" />
            </geometry>
            <material name="LightGrey">
                <color rgba="0.7 0.7 0.7 1.0" />
            </material>
        </visual>
        <collision>
            <origin rpy="1.57 0 0" xyz="0.0 0.0 0.09465" />
            <geometry>
                <!--  <mesh filename="package://ur_description/meshes/ur5/collision/wrist2.stl" /> -->
                <cylinder length="0.105" radius="0.0320" />
            </geometry>
        </collision>
        <inertial>
            <mass value="1.219" />
            <origin rpy="0 0 0" xyz="0.0 0.0 0.09465" />
            <inertia ixx="0.0025598989760400002" ixy="0.0" ixz="0.0" iyy="0.0025598989760400002" iyz="0.0" izz="0.0021942" />
        </inertial>
    </link>
    <joint name="wrist_3_joint" type="revolute">
        <parent link="wrist_2_link" />
        <child link="wrist_3_link" />
        <origin rpy="0.0 0.0 0.0" xyz="0.0 0.0 0.09465" />
        <axis xyz="0 1 0" />
        <limit effort="28.0" lower="-6.283185307179586" upper="6.283185307179586" velocity="3.2" />
        <dynamics damping="0.0" friction="0.0" />
    </joint>
    <link name="wrist_3_link">
        <visual>
            <geometry>
                <mesh filename="package://ur_description/meshes/ur5/visual/wrist3.dae" />
            </geometry>
            <material name="LightGrey">
                <color rgba="0.7 0.7 0.7 1.0" />
            </material>
        </visual>
        <collision>
            <origin rpy="1.57 0.0 0" xyz="0.0 0.067 0.0" />
            <geometry>
                <!--  <mesh filename="package://ur_description/meshes/ur5/collision/wrist3.stl" /> -->
                <cylinder length="0.0245" radius="0.0320" />
            </geometry>
        </collision>
        <inertial>
            <mass value="0.1879" />
            <origin rpy="1.5707963267948966 0 0" xyz="0.0 0.06505 0.0" />
            <inertia ixx="8.469589112163e-05" ixy="0.0" ixz="0.0" iyy="8.469589112163e-05" iyz="0.0" izz="0.0001321171875" />
        </inertial>
    </link>
    <joint name="ee_fixed_joint" type="fixed">
        <parent link="wrist_3_link" />
        <child link="ee_link" />
        <origin rpy="0.0 0.0 1.5707963267948966" xyz="0.0 0.0823 0.0" />
    </joint>
    <link name="ee_link">
        <collision>
            <geometry>
                <box size="0.01 0.01 0.01" />
            </geometry>
            <origin rpy="0 0 0" xyz="-0.01 0 0" />
        </collision>
        <inertial>
            <mass value="0.1" />
            <origin xyz="0 0 0" rpy="0 0 0" />
            <inertia ixx="0.03" iyy="0.03" izz="0.03" ixy="0.0" ixz="0.0" iyz="0.0" />
        </inertial>
    </link>
    <transmission name="shoulder_pan_trans">
        <type>transmission_interface/SimpleTransmission</type>
        <joint name="shoulder_pan_joint">
            <hardwareInterface>hardware_interface/PositionJointInterface</hardwareInterface>
        </joint>
        <actuator name="shoulder_pan_motor">
            <mechanicalReduction>1</mechanicalReduction>
            <hardwareInterface>hardware_interface/EffortJointInterface</hardwareInterface>
        </actuator>
    </transmission>
    <transmission name="shoulder_lift_trans">
        <type>transmission_interface/SimpleTransmission</type>
        <joint name="shoulder_lift_joint">
            <hardwareInterface>hardware_interface/PositionJointInterface</hardwareInterface>
        </joint>
        <actuator name="shoulder_lift_motor">
            <mechanicalReduction>1</mechanicalReduction>
            <hardwareInterface>hardware_interface/EffortJointInterface</hardwareInterface>
        </actuator>
    </transmission>
    <transmission name="elbow_trans">
        <type>transmission_interface/SimpleTransmission</type>
        <joint name="elbow_joint">
            <hardwareInterface>hardware_interface/PositionJointInterface</hardwareInterface>
        </joint>
        <actuator name="elbow_motor">
            <mechanicalReduction>1</mechanicalReduction>
            <hardwareInterface>hardware_interface/EffortJointInterface</hardwareInterface>
        </actuator>
    </transmission>
    <transmission name="wrist_1_trans">
        <type>transmission_interface/SimpleTransmission</type>
        <joint name="wrist_1_joint">
            <hardwareInterface>hardware_interface/PositionJointInterface</hardwareInterface>
        </joint>
        <actuator name="wrist_1_motor">
            <mechanicalReduction>1</mechanicalReduction>
            <hardwareInterface>hardware_interface/EffortJointInterface</hardwareInterface>
        </actuator>
    </transmission>
    <transmission name="wrist_2_trans">
        <type>transmission_interface/SimpleTransmission</type>
        <joint name="wrist_2_joint">
            <hardwareInterface>hardware_interface/PositionJointInterface</hardwareInterface>
        </joint>
        <actuator name="wrist_2_motor">
            <mechanicalReduction>1</mechanicalReduction>
            <hardwareInterface>hardware_interface/EffortJointInterface</hardwareInterface>
        </actuator>
    </transmission>
    <transmission name="wrist_3_trans">
        <type>transmission_interface/SimpleTransmission</type>
        <joint name="wrist_3_joint">
            <hardwareInterface>hardware_interface/PositionJointInterface</hardwareInterface>
        </joint>
        <actuator name="wrist_3_motor">
            <mechanicalReduction>1</mechanicalReduction>
            <hardwareInterface>hardware_interface/EffortJointInterface</hardwareInterface>
        </actuator>
    </transmission>
    <gazebo reference="shoulder_link">
        <selfCollide>true</selfCollide>
    </gazebo>
    <gazebo reference="upper_arm_link">
        <selfCollide>true</selfCollide>
    </gazebo>
    <gazebo reference="forearm_link">
        <selfCollide>true</selfCollide>
    </gazebo>
    <gazebo reference="wrist_1_link">
        <selfCollide>true</selfCollide>
    </gazebo>
    <gazebo reference="wrist_3_link">
        <selfCollide>true</selfCollide>
    </gazebo>
    <gazebo reference="wrist_2_link">
        <selfCollide>true</selfCollide>
    </gazebo>
    <gazebo reference="ee_link">
        <selfCollide>true</selfCollide>
    </gazebo>
    <!-- ROS base_link to UR 'Base' Coordinates transform -->
    <link name="base" />
    <joint name="base_link-base_fixed_joint" type="fixed">
        <!-- NOTE: this rotation is only needed as long as base_link itself is
                 not corrected wrt the real robot (ie: rotated over 180
                 degrees)
      -->
        <origin rpy="0 0 -3.141592653589793" xyz="0 0 0" />
        <parent link="base_link" />
        <child link="base" />
    </joint>
    <!-- Frame coincident with all-zeros TCP on UR controller -->
    <link name="tool0" />
    <joint name="wrist_3_link-tool0_fixed_joint" type="fixed">
        <origin rpy="-1.5707963267948966 0 0" xyz="0 0.0823 0" />
        <parent link="wrist_3_link" />
        <child link="tool0" />
    </joint>
    <joint name="ebot_joint" type="fixed">
        <parent link="hbot_base" />
        <child link="base_link" />
        <origin rpy="0.0 0.0 0" xyz="0.0 0 0.45" />
    </joint>
    <joint name="gripper_base_joint" type="fixed">
        <parent link="wrist_3_link" />
        <child link="gripper_base_link" />
        <origin rpy="0 0 1.5707963267948966" xyz="0 0.08 0" />
    </joint>
    <link name="gripper_base_link">
        <visual>
            <geometry>
                <mesh filename="package://robotiq_85_description/meshes/visual/robotiq_85_base_link.dae" />
            </geometry>
        </visual>
        <collision>
            <origin rpy="0 1.57 0" xyz="0.017 0 0" />
            <geometry>
                <!-- <mesh filename="package://robotiq_85_description/meshes/collision/robotiq_85_base_link.stl"/> -->
                <cylinder length="0.030" radius="0.0375" />
            </geometry>
        </collision>
        <inertial>
            <mass value="0.636951" />
            <origin xyz="0.0 0.0 0.0" rpy="0 0 0" />
            <inertia ixx="0.000380" ixy="0.000000" ixz="0.000000" iyx="0.000000" iyy="0.001110" iyz="0.000000" izx="0.000000" izy="0.000000" izz="0.001171" />
        </inertial>
    </link>
    <gazebo reference="gripper_base_link">
        <implicitSpringDamper>1</implicitSpringDamper>
        <mu1>100000</mu1>
        <mu2>100000</mu2>
        <kp>100000000.0</kp>
        <kd>1.0</kd>
    </gazebo>
    <joint name="gripper_finger1_joint" type="revolute">
        <parent link="gripper_base_link" />
        <child link="gripper_finger1_knuckle_link" />
        <axis xyz="0 0 1" />
        <origin rpy="3.141592653589793 0.0 0.0" xyz="0.05490451627 0.03060114443 0.0" />
        <limit effort="1000" lower="0.0" upper="0.804" velocity="2.0" />
    </joint>
    <joint name="gripper_finger2_joint" type="revolute">
        <parent link="gripper_base_link" />
        <child link="gripper_finger2_knuckle_link" />
        <axis xyz="0 0 1" />
        <origin rpy="0.0 0.0 0.0" xyz="0.05490451627 -0.03060114443 0.0" />
        <limit effort="1000" lower="-3.14" upper="3.14" velocity="100.0" />
        <mimic joint="gripper_finger1_joint" />
    </joint>
    <link name="gripper_finger1_knuckle_link">
        <visual>
            <geometry>
                <mesh filename="package://robotiq_85_description/meshes/visual/robotiq_85_knuckle_link.dae" />
            </geometry>
        </visual>
        <collision>
            <origin rpy="0 0 -0.0873" xyz="0 -0.01 0" />
            <geometry>
                <!-- <mesh filename="package://robotiq_85_description/meshes/collision/robotiq_85_knuckle_link.stl"/> -->
                <box size="0.012 0.035 0.014" />
            </geometry>
        </collision>
        <inertial>
            <mass value="0.018491" />
            <origin xyz="0.0 0.0 0.0" rpy="0 0 0" />
            <inertia ixx="0.000009" ixy="-0.000001" ixz="0.000000" iyx="-0.000001" iyy="0.000001" iyz="0.000000" izx="0.000000" izy="0.000000" izz="0.000010" />
        </inertial>
    </link>
    <gazebo reference="gripper_finger1_knuckle_link">
        <implicitSpringDamper>1</implicitSpringDamper>
        <mu1>100000</mu1>
        <mu2>100000</mu2>
        <kp>100000000.0</kp>
        <kd>1.0</kd>
    </gazebo>
    <link name="gripper_finger2_knuckle_link">
        <visual>
            <geometry>
                <mesh filename="package://robotiq_85_description/meshes/visual/robotiq_85_knuckle_link.dae" />
            </geometry>
        </visual>
        <collision>
            <origin rpy="0 0 -0.0873" xyz="0 -0.01 0" />
            <geometry>
                <!-- <mesh filename="package://robotiq_85_description/meshes/collision/robotiq_85_knuckle_link.stl"/> -->
                <box size="0.012 0.035 0.014" />
            </geometry>
        </collision>
        <inertial>
            <mass value="0.018491" />
            <origin xyz="0.0 0.0 0.0" rpy="0 0 0" />
            <inertia ixx="0.000009" ixy="-0.000001" ixz="0.000000" iyx="-0.000001" iyy="0.000001" iyz="0.000000" izx="0.000000" izy="0.000000" izz="0.000010" />
        </inertial>
    </link>
    <gazebo reference="gripper_finger2_knuckle_link">
        <implicitSpringDamper>1</implicitSpringDamper>
        <mu1>100000</mu1>
        <mu2>100000</mu2>
        <kp>100000000.0</kp>
        <kd>1.0</kd>
    </gazebo>
    <joint name="gripper_finger1_finger_joint" type="fixed">
        <parent link="gripper_finger1_knuckle_link" />
        <child link="gripper_finger1_finger_link" />
        <origin rpy="0 0 0" xyz="-0.00408552455 -0.03148604435 0.0" />
    </joint>
    <joint name="gripper_finger2_finger_joint" type="fixed">
        <parent link="gripper_finger2_knuckle_link" />
        <child link="gripper_finger2_finger_link" />
        <origin rpy="0 0 0" xyz="-0.00408552455 -0.03148604435 0.0" />
    </joint>
    <link name="gripper_finger1_finger_link">
        <visual>
            <geometry>
                <mesh filename="package://robotiq_85_description/meshes/visual/robotiq_85_finger_link.dae" />
            </geometry>
        </visual>
        <collision>
            <origin rpy="0 0 -0.175" xyz="0.025 -0.002 0" />
            <geometry>
                <!--  <mesh filename="package://robotiq_85_description/meshes/collision/robotiq_85_finger_link.stl"/> -->
                <box size="0.0591 0.010 0.020" />
            </geometry>
        </collision>
        <inertial>
            <mass value="0.027309" />
            <origin xyz="0.0 0.0 0.0" rpy="0 0 0" />
            <inertia ixx="0.000003" ixy="-0.000002" ixz="0.000000" iyx="-0.000002" iyy="0.000021" iyz="0.000000" izx="0.000000" izy="0.000000" izz="0.000020" />
        </inertial>
    </link>
    <gazebo reference="gripper_finger1_finger_link">
        <implicitSpringDamper>1</implicitSpringDamper>
        <mu1>100000</mu1>
        <mu2>100000</mu2>
        <kp>100000000.0</kp>
        <kd>1.0</kd>
    </gazebo>
    <link name="gripper_finger2_finger_link">
        <visual>
            <geometry>
                <mesh filename="package://robotiq_85_description/meshes/visual/robotiq_85_finger_link.dae" />
            </geometry>
        </visual>
        <collision>
            <origin rpy="0 0 -0.175" xyz="0.025 -0.002 0" />
            <geometry>
                <!--  <mesh filename="package://robotiq_85_description/meshes/collision/robotiq_85_finger_link.stl"/> -->
                <box size="0.0591 0.010 0.020" />
            </geometry>
        </collision>
        <inertial>
            <mass value="0.027309" />
            <origin xyz="0.0 0.0 0.0" rpy="0 0 0" />
            <inertia ixx="0.000003" ixy="-0.000002" ixz="0.000000" iyx="-0.000002" iyy="0.000021" iyz="0.000000" izx="0.000000" izy="0.000000" izz="0.000020" />
        </inertial>
    </link>
    <gazebo reference="gripper_finger2_finger_link">
        <implicitSpringDamper>1</implicitSpringDamper>
        <mu1>100000</mu1>
        <mu2>100000</mu2>
        <kp>100000000.0</kp>
        <kd>1.0</kd>
    </gazebo>
    <joint name="gripper_finger1_inner_knuckle_joint" type="continuous">
        <parent link="gripper_base_link" />
        <child link="gripper_finger1_inner_knuckle_link" />
        <axis xyz="0 0 1" />
        <origin rpy="3.141592653589793 0.0 0.0" xyz="0.06142 0.0127 0" />
        <limit effort="0.1" lower="-3.14" upper="3.14" velocity="100.0" />
        <mimic joint="gripper_finger1_joint" offset="0" />
    </joint>
    <joint name="gripper_finger2_inner_knuckle_joint" type="continuous">
        <parent link="gripper_base_link" />
        <child link="gripper_finger2_inner_knuckle_link" />
        <axis xyz="0 0 1" />
        <origin rpy="0 0 0" xyz="0.06142 -0.0127 0" />
        <limit effort="0.1" lower="-3.14" upper="3.14" velocity="100.0" />
        <mimic joint="gripper_finger1_joint" offset="0" />
    </joint>
    <link name="gripper_finger1_inner_knuckle_link">
        <visual>
            <geometry>
                <mesh filename="package://robotiq_85_description/meshes/visual/robotiq_85_inner_knuckle_link.dae" />
            </geometry>
        </visual>
        <collision>
            <origin rpy="0 0 -0.698" xyz="0.025 -0.02 0" />
            <geometry>
                <!--    <mesh filename="package://robotiq_85_description/meshes/collision/robotiq_85_inner_knuckle_link.stl"/> -->
                <box size="0.055 0.006 0.020" />
            </geometry>
        </collision>
        <inertial>
            <mass value="0.029951" />
            <origin xyz="0.0 0.0 0.0" rpy="0 0 0" />
            <inertia ixx="0.000039" ixy="0.000000" ixz="0.000000" iyx="0.000000" iyy="0.000005" iyz="0.000000" izx="0.000000" izy="0.000000" izz="0.000035" />
        </inertial>
    </link>
    <gazebo reference="gripper_finger1_inner_knuckle_link">
        <implicitSpringDamper>1</implicitSpringDamper>
        <mu1>100000</mu1>
        <mu2>100000</mu2>
        <kp>100000000.0</kp>
        <kd>1.0</kd>
    </gazebo>
    <link name="gripper_finger2_inner_knuckle_link">
        <visual>
            <geometry>
                <mesh filename="package://robotiq_85_description/meshes/visual/robotiq_85_inner_knuckle_link.dae" />
            </geometry>
        </visual>
        <collision>
            <origin rpy="0 0 -0.698" xyz="0.025 -0.02 0" />
            <geometry>
                <!--   <mesh filename="package://robotiq_85_description/meshes/collision/robotiq_85_inner_knuckle_link.stl"/> -->
                <box size="0.055 0.006 0.020" />
            </geometry>
        </collision>
        <inertial>
            <mass value="0.029951" />
            <origin xyz="0.0 0.0 0.0" rpy="0 0 0" />
            <inertia ixx="0.000039" ixy="0.000000" ixz="0.000000" iyx="0.000000" iyy="0.000005" iyz="0.000000" izx="0.000000" izy="0.000000" izz="0.000035" />
        </inertial>
    </link>
    <gazebo reference="gripper_finger2_inner_knuckle_link">
        <implicitSpringDamper>1</implicitSpringDamper>
        <mu1>100000</mu1>
        <mu2>100000</mu2>
        <kp>100000000.0</kp>
        <kd>1.0</kd>
    </gazebo>
    <joint name="gripper_finger1_finger_tip_joint" type="continuous">
        <parent link="gripper_finger1_inner_knuckle_link" />
        <child link="gripper_finger1_finger_tip_link" />
        <axis xyz="0 0 1" />
        <origin rpy="0.0 0.0 0.0" xyz="0.04303959807 -0.03759940821 0.0" />
        <limit effort="100" lower="-3.14" upper="3.14" velocity="100.0" />
        <mimic joint="gripper_finger1_joint" multiplier="-1" />
    </joint>
    <joint name="gripper_finger2_finger_tip_joint" type="continuous">
        <parent link="gripper_finger2_inner_knuckle_link" />
        <child link="gripper_finger2_finger_tip_link" />
        <axis xyz="0 0 1" />
        <origin rpy="0.0 0.0 0.0" xyz="0.04303959807 -0.03759940821  0.0" />
        <limit effort="100" lower="-3.14" upper="3.14" velocity="100.0" />
        <mimic joint="gripper_finger1_joint" multiplier="-1" />
    </joint>
    <link name="gripper_finger1_finger_tip_link">
        <visual>
            <geometry>
                <mesh filename="package://robotiq_85_description/meshes/visual/robotiq_85_finger_tip_link.dae" />
            </geometry>
        </visual>
        <collision>
            <origin rpy="0 0 0" xyz="0.02 0 0" />
            <geometry>
                <!--  <mesh filename="package://robotiq_85_description/meshes/collision/robotiq_85_finger_tip_link.stl"/> -->
                <box size="0.045 0.01 0.02" />
            </geometry>
        </collision>
        <inertial>
            <mass value="0.019555" />
            <origin xyz="0.0 0.0 0.0" rpy="0 0 0" />
            <inertia ixx="0.000002" ixy="0.000000" ixz="0.000000" iyx="0.000000" iyy="0.000005" iyz="0.000000" izx="0.000000" izy="0.000000" izz="0.000006" />
        </inertial>
    </link>
    <gazebo reference="gripper_finger1_finger_tip_link">
        <implicitSpringDamper>1</implicitSpringDamper>
        <mu1>100000</mu1>
        <mu2>100000</mu2>
        <kp>100000000.0</kp>
        <kd>1.0</kd>
    </gazebo>
    <link name="gripper_finger2_finger_tip_link">
        <visual>
            <geometry>
                <mesh filename="package://robotiq_85_description/meshes/visual/robotiq_85_finger_tip_link.dae" />
            </geometry>
        </visual>
        <collision>
            <origin rpy="0 0 0" xyz="0.02 0 0" />
            <geometry>
                <!-- <mesh filename="package://robotiq_85_description/meshes/collision/robotiq_85_finger_tip_link.stl"/> -->
                <box size="0.045 0.01 0.02" />
            </geometry>
        </collision>
        <inertial>
            <mass value="0.019555" />
            <origin xyz="0.0 0.0 0.0" rpy="0 0 0" />
            <inertia ixx="0.000002" ixy="0.000000" ixz="0.000000" iyx="0.000000" iyy="0.000005" iyz="0.000000" izx="0.000000" izy="0.000000" izz="0.000006" />
        </inertial>
    </link>
    <gazebo reference="gripper_finger2_finger_tip_link">
        <implicitSpringDamper>1</implicitSpringDamper>
        <mu1>100000</mu1>
        <mu2>100000</mu2>
        <kp>100000000.0</kp>
        <kd>1.0</kd>
    </gazebo>
    <!-- 	<gazebo>
	  <plugin name="gazebo_grasp_fix" filename="libgazebo_grasp_fix.so">
            <arm>
              <arm_name>gripper_arm</arm_name>
              <palm_link>${parent}</palm_link>
              <gripper_link>${prefix}gripper_finger1_finger_tip_link</gripper_link>
              <gripper_link>${prefix}gripper_finger2_finger_tip_link</gripper_link>
            </arm>
	    <forces_angle_tolerance>100</forces_angle_tolerance>
	    <update_rate>2</update_rate>
	    <grip_count_threshold>1</grip_count_threshold>
	    <max_grip_count>2</max_grip_count>
	    <release_tolerance>0.005</release_tolerance>
	    <disable_collisions_on_attach>true</disable_collisions_on_attach>
	    <contact_topic>__default_topic__</contact_topic>
	  </plugin>
	</gazebo> -->
    <transmission name="gripper_finger1_trans">
        <type>transmission_interface/SimpleTransmission</type>
        <joint name="gripper_finger1_joint">
            <hardwareInterface>PositionJointInterface</hardwareInterface>
        </joint>
        <actuator name="gripper_finger1_motor">
            <mechanicalReduction>1</mechanicalReduction>
            <hardwareInterface>PositionJointInterface</hardwareInterface>
        </actuator>
    </transmission>
    <gazebo>
        <!-- loading plugin: mimic joints works in gazebo now -->
        <plugin filename="libroboticsgroup_gazebo_mimic_joint_plugin.so" name="mimic_robotiq_85_1">
            <joint>gripper_finger1_joint</joint>
            <mimicJoint>gripper_finger2_joint</mimicJoint>
            <!--multiplier>1.0</multiplier>
                <offset>0.0</offset-->
        </plugin>
        <plugin filename="libroboticsgroup_gazebo_mimic_joint_plugin.so" name="mimic_robotiq_85_2">
            <joint>gripper_finger1_joint</joint>
            <mimicJoint>gripper_finger2_inner_knuckle_joint</mimicJoint>
            <!--multiplier>1.0</multiplier>
                <offset>0.0</offset-->
        </plugin>
        <plugin filename="libroboticsgroup_gazebo_mimic_joint_plugin.so" name="mimic_robotiq_85_3">
            <joint>gripper_finger1_joint</joint>
            <mimicJoint>gripper_finger1_inner_knuckle_joint</mimicJoint>
            <!--multiplier>1.0</multiplier>
                <offset>0.0</offset-->
        </plugin>
        <plugin filename="libroboticsgroup_gazebo_mimic_joint_plugin.so" name="mimic_robotiq_85_4">
            <joint>gripper_finger1_joint</joint>
            <mimicJoint>gripper_finger1_finger_tip_joint</mimicJoint>
            <multiplier>-1.0</multiplier>
            <offset>0.0</offset>
        </plugin>
        <plugin filename="libroboticsgroup_gazebo_mimic_joint_plugin.so" name="mimic_robotiq_85_5">
            <joint>gripper_finger1_joint</joint>
            <mimicJoint>gripper_finger2_finger_tip_joint</mimicJoint>
            <multiplier>-1.0</multiplier>
            <offset>0.0</offset>
        </plugin>
    </gazebo>
    <joint name="intelrealsense2" type="fixed">
        <axis xyz="0 0 0" />
        <origin rpy="3.14 0 1.57" xyz="0 0.25 -0.08" />
        <parent link="wrist_3_link" />
        <child link="camera_link2" />
    </joint>
    <link name="camera_link2">
        <collision>
            <origin rpy="0 0 0" xyz="0.02 0 0" />
            <geometry>
                <box size="0.001 0.001 0.001" />
            </geometry>
        </collision>
        <visual>
            <origin rpy="1.5707 0 1.5707" xyz="0 0 0" />
            <geometry>
                <mesh filename="package://eyrc-2022_krishibot/meshes/NAVRS.STL" />
            </geometry>
        </visual>
        <inertial>
            <mass value="1e-5" />
            <origin rpy="0 0 0" xyz="0 0 0" />
            <inertia ixx="0" ixy="0" ixz="0" iyy="0" iyz="0" izz="0" />
        </inertial>
    </link>
    <joint name="camera_optical_joint2" type="fixed">
        <origin rpy="-1.5707963267948966 0 -1.5707963267948966" xyz="0 0 0" />
        <parent link="camera_link2" />
        <child link="camera_rgb_frame2" />
    </joint>
    <link name="camera_rgb_frame2" />
    <joint name="camera_depth_joint2" type="fixed">
        <origin rpy="-1.5707963267948966 0 -1.5707963267948966" xyz="0 0 0" />
        <parent link="camera_link2" />
        <child link="camera_depth_frame2" />
    </joint>
    <link name="camera_depth_frame2" />
    <joint name="base_camera" type="fixed">
        <axis xyz="0 0 0" />
        <origin rpy="6.28 -0.2 -6.28" xyz="0.22 0 0.000" />
        <parent link="lidar_1_1" />
        <child link="base_camera_link" />
    </joint>
    <link name="base_camera_link">
        <collision>
            <origin rpy="0 0 0" xyz="0.02 0 0" />
            <geometry>
                <box size="0.001 0.001 0.001" />
            </geometry>
        </collision>
        <visual>
            <origin rpy="1.5707 0 1.5707" xyz="0 0 0" />
            <geometry>
                <mesh filename="package://eyrc-2022_krishibot/meshes/NAVRS.STL" />
            </geometry>
        </visual>
        <inertial>
            <mass value="1e-5" />
            <origin rpy="0 0 0" xyz="0 0 0" />
            <inertia ixx="0" ixy="0" ixz="0" iyy="0" iyz="0" izz="0" />
        </inertial>
    </link>
    <joint name="base_camera_optical_joint" type="fixed">
        <origin rpy="-1.5707963267948966 0 -1.5707963267948966" xyz="0 0 0" />
        <parent link="base_camera_link" />
        <child link="base_camera_rgb_frame" />
    </joint>
    <link name="base_camera_rgb_frame" />
    <joint name="base_camera_depth_joint" type="fixed">
        <origin rpy="-1.5707963267948966 0 -1.5707963267948966" xyz="0 0 0" />
        <parent link="base_camera_link" />
        <child link="base_camera_depth_frame" />
    </joint>
    <link name="base_camera_depth_frame" />
    <gazebo reference="camera_link2">
        <sensor name="intelrealsense2" type="depth">
            <always_on>1</always_on>
            <visualize>true</visualize>
            <camera>
                <horizontal_fov>1.047</horizontal_fov>
                <image>
                    <width>640</width>
                    <height>480</height>
                    <format>R8G8B8</format>
                </image>
                <depth_camera />
                <clip>
                    <near>0.1</near>
                    <far>100</far>
                </clip>
            </camera>
            <plugin filename="libgazebo_ros_openni_kinect.so" name="intelrealsense">
                <alwaysOn>true</alwaysOn>
                <updateRate>10.0</updateRate>
                <cameraName>camera2</cameraName>
                <frameName>camera_depth_frame2</frameName>
                <imageTopicName>/camera/color/image_raw2</imageTopicName>
                <depthImageTopicName>/camera/depth/image_raw2</depthImageTopicName>
                <pointCloudTopicName>depth/points2</pointCloudTopicName>
                <cameraInfoTopicName>/camera/color/camera_info2</cameraInfoTopicName>
                <depthImageCameraInfoTopicName>/camera/depth/camera_info2</depthImageCameraInfoTopicName>
                <pointCloudCutoff>0.2</pointCloudCutoff>
                <pointCloudCutoffMax>10.0</pointCloudCutoffMax>
                <hackBaseline>0.07</hackBaseline>
                <distortionK1>0.0</distortionK1>
                <distortionK2>0.0</distortionK2>
                <distortionK3>0.0</distortionK3>
                <distortionT1>0.0</distortionT1>
                <distortionT2>0.0</distortionT2>
                <CxPrime>0.0</CxPrime>
                <Cx>0.0</Cx>
                <Cy>0.0</Cy>
                <focalLength>0.0</focalLength>
            </plugin>
        </sensor>
    </gazebo>
    <gazebo reference="base_camera_link">
        <sensor name="intelrealsense1" type="depth">
            <always_on>1</always_on>
            <visualize>true</visualize>
            <camera>
                <horizontal_fov>1.047</horizontal_fov>
                <image>
                    <width>640</width>
                    <height>480</height>
                    <format>R8G8B8</format>
                </image>
                <depth_camera />
                <clip>
                    <near>0.1</near>
                    <far>100</far>
                </clip>
            </camera>
            <plugin filename="libgazebo_ros_openni_kinect.so" name="intelrealsense1">
                <alwaysOn>true</alwaysOn>
                <updateRate>10.0</updateRate>
                <cameraName>base_camera</cameraName>
                <frameName>base_camera_depth_frame</frameName>
                <imageTopicName>/camera1/color/image_raw1</imageTopicName>
                <depthImageTopicName>/camera1/depth/image_raw1</depthImageTopicName>
                <pointCloudTopicName>depth1/points1</pointCloudTopicName>
                <cameraInfoTopicName>/camera1/color/camera_info1</cameraInfoTopicName>
                <depthImageCameraInfoTopicName>/camera1/depth/camera_info1</depthImageCameraInfoTopicName>
                <pointCloudCutoff>0.2</pointCloudCutoff>
                <pointCloudCutoffMax>10.0</pointCloudCutoffMax>
                <hackBaseline>0.07</hackBaseline>
                <distortionK1>0.0</distortionK1>
                <distortionK2>0.0</distortionK2>
                <distortionK3>0.0</distortionK3>
                <distortionT1>0.0</distortionT1>
                <distortionT2>0.0</distortionT2>
                <CxPrime>0.0</CxPrime>
                <Cx>0.0</Cx>
                <Cy>0.0</Cy>
                <focalLength>0.0</focalLength>
            </plugin>
        </sensor>
    </gazebo>
    <transmission name="trans_gripper_finger2_joint">
        <type>transmission_interface/SimpleTransmission</type>
        <joint name="gripper_finger2_joint">
            <hardwareInterface>hardware_interface/EffortJointInterface</hardwareInterface>
        </joint>
        <actuator name="gripper_finger2_joint_motor">
            <hardwareInterface>hardware_interface/EffortJointInterface</hardwareInterface>
            <mechanicalReduction>1</mechanicalReduction>
        </actuator>
    </transmission>
    <transmission name="trans_gripper_finger1_inner_knuckle_joint">
        <type>transmission_interface/SimpleTransmission</type>
        <joint name="gripper_finger1_inner_knuckle_joint">
            <hardwareInterface>hardware_interface/EffortJointInterface</hardwareInterface>
        </joint>
        <actuator name="gripper_finger1_inner_knuckle_joint_motor">
            <hardwareInterface>hardware_interface/EffortJointInterface</hardwareInterface>
            <mechanicalReduction>1</mechanicalReduction>
        </actuator>
    </transmission>
    <transmission name="trans_gripper_finger2_inner_knuckle_joint">
        <type>transmission_interface/SimpleTransmission</type>
        <joint name="gripper_finger2_inner_knuckle_joint">
            <hardwareInterface>hardware_interface/EffortJointInterface</hardwareInterface>
        </joint>
        <actuator name="gripper_finger2_inner_knuckle_joint_motor">
            <hardwareInterface>hardware_interface/EffortJointInterface</hardwareInterface>
            <mechanicalReduction>1</mechanicalReduction>
        </actuator>
    </transmission>
    <transmission name="trans_gripper_finger1_finger_tip_joint">
        <type>transmission_interface/SimpleTransmission</type>
        <joint name="gripper_finger1_finger_tip_joint">
            <hardwareInterface>hardware_interface/EffortJointInterface</hardwareInterface>
        </joint>
        <actuator name="gripper_finger1_finger_tip_joint_motor">
            <hardwareInterface>hardware_interface/EffortJointInterface</hardwareInterface>
            <mechanicalReduction>1</mechanicalReduction>
        </actuator>
    </transmission>
    <transmission name="trans_gripper_finger2_finger_tip_joint">
        <type>transmission_interface/SimpleTransmission</type>
        <joint name="gripper_finger2_finger_tip_joint">
            <hardwareInterface>hardware_interface/EffortJointInterface</hardwareInterface>
        </joint>
        <actuator name="gripper_finger2_finger_tip_joint_motor">
            <hardwareInterface>hardware_interface/EffortJointInterface</hardwareInterface>
            <mechanicalReduction>1</mechanicalReduction>
        </actuator>
    </transmission>
</robot>

